<mujoco model="x2t2.5">
  <compiler angle="radian" meshdir="assets" autolimits="true"/>

  <default>
    <default class="x2">
      <joint armature="0.01" frictionloss="0.3"/>
      <default class="visual">
        <geom group="2" type="mesh" density="0" material="silver" contype="0" conaffinity="0"/>
      </default>
      <default class="collision">
        <geom group="3" rgba=".2 .6 .2 .3" type="capsule" contype="1" conaffinity="1"/>
        <default class="foot">
          <geom type="sphere" size="0.003" priority="1" friction="0.6" condim="3"/>
        </default>
        <default class="foot_capsule">
          <geom type="capsule" size="0.005" friction="0.6" condim="3"/>
        </default>
      </default>
      <site group="5" rgba="1 0 0 1"/>
    </default>
  </default>

  <asset>
    <material name="white" rgba="1 1 1 1" />
    <material name="yellow" rgba="1.0 0.5 0.0 1" />
    <material name="silver" rgba="0.7 0.7 0.7 1"/>
    <material name="black" rgba="0.2 0.2 0.2 1"/>
    <material name="default_material" rgba="0.7 0.7 0.7 1" />
    <material name="collision_material" rgba="1.0 0.28 0.1 0.9" />

    <mesh name="pelvis" file="pelvis.STL" />
    <mesh name="imu_in_pelvis" file="imu_in_pelvis_link.STL" />
    <mesh name="left_hip_pitch_link" file="left_hip_pitch_link.STL" />
    <mesh name="left_hip_roll_link" file="left_hip_roll_link.STL" />
    <mesh name="left_hip_yaw_link" file="left_hip_yaw_link.STL" />
    <mesh name="left_knee_link" file="left_knee_link.STL" />
    <mesh name="left_ankle_pitch_link" file="left_ankle_pitch_link.STL" />
    <mesh name="left_ankle_roll_link" file="left_ankle_roll_link.STL" />
    <mesh name="right_hip_pitch_link" file="right_hip_pitch_link.STL" />
    <mesh name="right_hip_roll_link" file="right_hip_roll_link.STL" />
    <mesh name="right_hip_yaw_link" file="right_hip_yaw_link.STL" />
    <mesh name="right_knee_link" file="right_knee_link.STL" />
    <mesh name="right_ankle_pitch_link" file="right_ankle_pitch_link.STL" />
    <mesh name="right_ankle_roll_link" file="right_ankle_roll_link.STL" />
    <mesh name="waist_yaw_link" file="waist_yaw_link.STL" />
    <mesh name="waist_pitch_link" file="waist_pitch_link.STL" />
    <mesh name="torso_link" file="torso_plus_link.STL" />
    <mesh name="imu_in_torso_link" file="imu_in_torso_link.STL" />
    <mesh name="left_shoulder_pitch_link" file="left_shoulder_pitch_link.STL" />
    <mesh name="left_shoulder_roll_link" file="left_shoulder_roll_link.STL" />
    <mesh name="left_shoulder_yaw_link" file="left_shoulder_yaw_link.STL" />
    <mesh name="left_elbow_link" file="left_elbow_link.STL" />
    <mesh name="left_wrist_yaw_link" file="left_wrist_yaw_link.STL" />
    <mesh name="left_wrist_pitch_link" file="left_wrist_pitch_link.STL" />
    <mesh name="left_wrist_roll_link" file="left_wrist_roll_link.STL" />
    <mesh name="right_shoulder_pitch_link" file="right_shoulder_pitch_link.STL" />
    <mesh name="right_shoulder_roll_link" file="right_shoulder_roll_link.STL" />
    <mesh name="right_shoulder_yaw_link" file="right_shoulder_yaw_link.STL" />
    <mesh name="right_elbow_link" file="right_elbow_link.STL" />
    <mesh name="right_wrist_yaw_link" file="right_wrist_yaw_link.STL" />
    <mesh name="right_wrist_pitch_link" file="right_wrist_pitch_link.STL" />
    <mesh name="right_wrist_roll_link" file="right_wrist_roll_link.STL" />
    <mesh name="head_yaw_link" file="head_yaw_link.STL" />
    <mesh name="head_pitch_link" file="head_pitch_link.STL" />
    <mesh name="imu_in_head_link" file="imu_in_head_link.STL" />
    <mesh name="rgbd_head_front_link" file="rgbd_head_front_link.STL" />
    <mesh name="stereo_head_front_link" file="stereo_head_front_link.STL" />
    <mesh name="rgb_head_rear_link" file="rgb_head_rear_link.STL" />
    <mesh name="rgb_head_center_link" file="rgb_head_center_link.STL" />
  </asset>

  <worldbody>
    <light pos="1 0 3.5" dir="0 0 -1" directional="true"/>
    <body name="pelvis" pos="0 0 0.67495000" quat="1 0 0 0" childclass="x2">
      <inertial pos="0 0 -0.069" quat="1 0 0 0" mass="3.2" diaginertia="0.0085 0.0078 0.0068"/>
      <freejoint name="floating_base_joint" />
      <geom class="visual" material="black" mesh="pelvis"/>
      <geom name="pelvis_collision" class="collision" type="sphere" size="0.07" pos="0 0 0.01"/>
      <site name="imu_in_pelvis" size="0.01" pos="0.0239 -0.00023 0.04171"/>
      <body name="left_hip_pitch_link" pos="0 0.0713499997541465 0" quat="1.0 0.0 0.0 0.0">
        <inertial pos="0.00791 0.064136 0.000116" quat="1.0 0.0 0.0 0.0" mass="1.399682" diaginertia="0.007995 0.001639 0.007409" />
        <joint name="left_hip_pitch_joint" axis="0 1 0" range="-2.704 2.556" />
        <geom class="visual" material="black" mesh="left_hip_pitch_link"/>
        <body name="left_hip_roll_link" pos="-0.000574999999960968 0.0657000000000312 0" quat="1.0 0.0 0.0 0.0">
          <inertial pos="4.7e-05 0.000231 -0.093505" quat="1.0 0.0 0.0 0.0" mass="1.584804" diaginertia="0.017671 0.018102 0.002515" />
          <joint name="left_hip_roll_joint" axis="1 0 0"  range="-0.235 2.906" />
          <geom class="visual" mesh="left_hip_roll_link"/>
          <geom name="left_hip_collision" class="collision" size="0.06" fromto="0.02 0 0 0.02 0 -0.08"/>
          <body name="left_hip_yaw_link" pos="0.000574999999972778 0 -0.136850000000045" quat="1.0 0.0 0.0 0.0">
            <inertial pos="-0.002375 0.003914 -0.144276" quat="1.0 0.0 0.0 0.0" mass="2.010551" diaginertia="0.051974 0.052639 0.002467" />
            <joint name="left_hip_yaw_joint" axis="0 0 1" range="-1.684 3.43" />
            <geom class="visual" mesh="left_hip_yaw_link"/>
            <geom name="left_thigh_collision" class="collision" size="0.055" fromto="-0.0 0 -0.03 -0.02 0 -0.17"/>
            <body name="left_knee_link" pos="-0.00765999999995284 0.000225000000070329 -0.18309999999998" quat="1.0 0.0 0.0 0.0">
              <inertial pos="-0.002655 0.003681 -0.122697" quat="1.0 0.0 0.0 0.0" mass="1.568215" diaginertia="0.030979 0.030995 0.001942" />
              <joint name="left_knee_joint" axis="0 1 0" range="0 2.4073" />
              <geom class="visual" mesh="left_knee_link"/>
              <geom name="left_shin_collision" class="collision" size="0.045" fromto="0.01 0 0 0.01 0 -0.13"/>
              <geom name="left_linkage_brace_collision" class="collision" size="0.03" fromto="0.01 0 -0.18 0.01 0 -0.25"/>
              <body name="left_ankle_pitch_link" pos="-0.0100000000000136 -0.000124910735236235 -0.282000000000081" quat="1.0 0.0 0.0 0.0">
                <inertial pos="0.011691 -0.000181 0.003548" quat="1.0 0.0 0.0 0.0" mass="0.747802" diaginertia="0.000985 0.001162 0.000722" />
                <joint name="left_ankle_pitch_joint" axis="0 1 0" range="-0.803 0.453" />
                <geom class="visual" mesh="left_ankle_pitch_link"/>
                <body name="left_ankle_roll_link" pos="-0.00174999998947351 0 0" quat="1.0 0.0 0.0 0.0">
                  <site name="left_foot" rgba="1 0 0 1" pos="0.04 0 -0.037"/>
                  <inertial pos="0.035428 2.5e-05 -0.049572" quat="1.0 0.0 0.0 0.0" mass="1.016166" diaginertia="0.0037 0.007937 0.005766" />
                  <joint name="left_ankle_roll_joint" axis="1 0 0" range="-0.262 0.262" />
                  <geom class="visual" material="black" mesh="left_ankle_roll_link"/>
                  <geom name="left_foot_contact_0_geom" class="foot" pos="-0.05 0.05 -0.068"/>
                  <geom name="left_foot_contact_1_geom" class="foot" pos="-0.05 -0.05 -0.068"/>
                  <geom name="left_foot_contact_2_geom" class="foot" pos="0.11 0.05 -0.068"/>
                  <geom name="left_foot_contact_3_geom" class="foot" pos="0.11 -0.05 -0.068"/>

                  <geom name="left_foot1_collision" class="foot_capsule" fromto="0.1 -0.04 -0.068 0.05 -0.04 -0.025"/>
                  <geom name="left_foot2_collision" class="foot_capsule" fromto="-0.05 -0.025 -0.068 0.09 -0.025 -0.068"/>
                  <geom name="left_foot3_collision" class="foot_capsule" fromto="-0.055 -0.01 -0.068 0.10 -0.01 -0.068"/>
                  <geom name="left_foot4_collision" class="foot_capsule" fromto="-0.065 0 -0.068 0.11 0 -0.068"/>
                  <geom name="left_foot5_collision" class="foot_capsule" fromto="-0.055 0.01 -0.068 0.10 0.01 -0.068"/>
                  <geom name="left_foot6_collision" class="foot_capsule" fromto="-0.05 0.025 -0.068 0.09 0.025 -0.068"/>
                  <geom name="left_foot7_collision" class="foot_capsule" fromto="0.1 0.04 -0.068 0.05 0.04 -0.068"/>
                </body>
              </body>
            </body>
          </body>
        </body>
      </body>
      <body name="right_hip_pitch_link" pos="0 -0.0713499997541464 0" quat="1.0 0.0 0.0 0.0">
        <inertial pos="0.007909 -0.064114 0.000131" quat="1.0 0.0 0.0 0.0" mass="1.400227" diaginertia="0.007996 0.00164 0.007409" />
        <joint name="right_hip_pitch_joint" axis="0 1 0" range="-2.704 2.556"/>
        <geom class="visual" material="black" mesh="right_hip_pitch_link"/>
        <body name="right_hip_roll_link" pos="0 -0.0657000004916197 0" quat="1.0 0.0 0.0 0.0">
          <inertial pos="-0.000586 -0.000228 -0.093568" quat="1.0 0.0 0.0 0.0" mass="1.585084" diaginertia="0.017694 0.018116 0.002516" />
          <joint name="right_hip_roll_joint" axis="1 0 0"  range="-2.906 0.235" />
          <geom class="visual" mesh="right_hip_roll_link"/>
          <geom name="right_hip_collision" class="collision" size="0.06" fromto="0.02 0 0 0.02 0 -0.08"/>
          <body name="right_hip_yaw_link" pos="0 0 -0.136850000000023" quat="1.0 0.0 0.0 0.0">
            <inertial pos="-0.002444 -0.003935 -0.144335" quat="1.0 0.0 0.0 0.0" mass="2.002622" diaginertia="0.051833 0.052497 0.002461" />
            <joint name="right_hip_yaw_joint"  axis="0 0 1" range="-3.43 1.684"/>
            <geom class="visual" mesh="right_hip_yaw_link"/>
            <geom name="right_thigh_collision" class="collision" size="0.055" fromto="-0.0 0 -0.03 -0.02 0 -0.17"/>
            <body name="right_knee_link" pos="-0.00766000000003646 -0.000225000000000253 -0.183100000000014" quat="1.0 0.0 0.0 0.0">
              <inertial pos="-0.002699 -0.003794 -0.122288" quat="1.0 0.0 0.0 0.0" mass="1.565881" diaginertia="0.03081 0.030822 0.001935" />
              <joint name="right_knee_joint" axis="0 1 0" range="0 2.4073" />
              <geom class="visual" mesh="right_knee_link"/>
              <geom name="right_shin_collision" class="collision" size="0.045" fromto="0.01 0 0 0.01 0 -0.13"/>
              <geom name="right_linkage_brace_collision" class="collision" size="0.03" fromto="0.01 0 -0.18 0.01 0 -0.25"/>
              <body name="right_ankle_pitch_link" pos="-0.00999999999984942 0.000124910735223305 -0.282000000000021" quat="1.0 0.0 0.0 0.0">
                <inertial pos="0.011665 0.000937 0.00394" quat="1.0 0.0 0.0 0.0" mass="0.749566" diaginertia="0.001037 0.001214 0.000723" />
                <joint name="right_ankle_pitch_joint" axis="0 1 0" range="-0.803 0.453"/>
                <geom class="visual" mesh="right_ankle_pitch_link"/>
                <body name="right_ankle_roll_link" pos="-0.00174999998537372 0 0" quat="1.0 0.0 0.0 0.0">
                  <site name="right_foot" rgba="1 0 0 1" pos="0.04 0 -0.037"/>
                  <inertial pos="0.035428 2.5e-05 -0.049572" quat="1.0 0.0 0.0 0.0" mass="1.016166" diaginertia="0.0037 0.007937 0.005766" />
                  <joint name="right_ankle_roll_joint" axis="1 0 0"  range="-0.2625 0.2625" />
                  <geom class="visual" material="black" mesh="right_ankle_roll_link"/>
                  <geom name="right_foot_contact_0_geom" class="foot" pos="-0.05 0.05 -0.068"/>
                  <geom name="right_foot_contact_1_geom" class="foot" pos="-0.05 -0.05 -0.068"/>
                  <geom name="right_foot_contact_2_geom" class="foot" pos="0.11 0.05 -0.068"/>
                  <geom name="right_foot_contact_3_geom" class="foot" pos="0.11 -0.05 -0.068"/>

                  <geom name="right_foot1_collision" class="foot_capsule" fromto="0.1 -0.04 -0.068 0.05 -0.04 -0.025"/>
                  <geom name="right_foot2_collision" class="foot_capsule" fromto="-0.05 -0.025 -0.068 0.09 -0.025 -0.068"/>
                  <geom name="right_foot3_collision" class="foot_capsule" fromto="-0.055 -0.01 -0.068 0.10 -0.01 -0.068"/>
                  <geom name="right_foot4_collision" class="foot_capsule" fromto="-0.065 0 -0.068 0.11 0 -0.068"/>
                  <geom name="right_foot5_collision" class="foot_capsule" fromto="-0.055 0.01 -0.068 0.10 0.01 -0.068"/>
                  <geom name="right_foot6_collision" class="foot_capsule" fromto="-0.05 0.025 -0.068 0.09 0.025 -0.068"/>
                  <geom name="right_foot7_collision" class="foot_capsule" fromto="0.1 0.04 -0.068 0.05 0.04 -0.068"/>
                 </body>
              </body>
            </body>
          </body>
        </body>
      </body>
      <body name="waist_yaw_link" pos="0 0 0.0670600000000297" quat="1.0 0.0 0.0 0.0">
        <inertial pos="-0.001359 4.7e-05 0.041703" quat="1.0 0.0 0.0 0.0" mass="1.668542" diaginertia="0.005012 0.005 0.002852" />
        <joint name="waist_yaw_joint" axis="0 0 1" range="-3.43 2.382" />
        <geom class="visual" mesh="waist_yaw_link"/>
        <body name="waist_pitch_link" pos="0 0 0.0880106468356499" quat="1.0 0.0 0.0 0.0">
          <inertial pos="0.008967 -1e-06 0.0" quat="1.0 0.0 0.0 0.0" mass="0.392413" diaginertia="0.000133 0.000133 0.00023" />
          <joint name="waist_pitch_joint" axis="0 1 0"  range="-0.314 0.314" />
          <geom class="visual" mesh="waist_pitch_link" />
          <body name="torso_link" pos="0 0 0" quat="1.0 0.0 0.0 0.0">
            <inertial pos="-0.000188 0.000605 0.191827" quat="1.0 0.0 0.0 0.0" mass="10.144138" diaginertia="0.479751 0.455998 0.066754" />
            <joint name="waist_roll_joint" axis="1 0 0" range="-0.488 0.488"  />
            <geom class="visual" mesh="torso_link"/>
            <geom name="torso_collision" class="collision" size="0.09" fromto="0.01 0 0.08 0.01 0 0.2"/>
            <site name="imu_in_torso" size="0.01" pos="-0.02488 0.001985 0.105938"/>
            <body name="left_shoulder_pitch_link" pos="0.00329906676354264 0.143031506663431 0.241647721005027" quat="0.9945218983191807 0.10452843519164168 0.0 0.0">
              <inertial pos="0.003007 0.050014 6.2e-05" quat="1.0 0.0 0.0 0.0" mass="0.885896" diaginertia="0.003023 0.000685 0.002929" />
              <joint name="left_shoulder_pitch_joint" axis="0 1 0" range="-3.08 2.04" />
              <geom class="visual" mesh="left_shoulder_pitch_link"/>
              <body name="left_shoulder_roll_link" pos="-0.000499991072907324 0.0495 0" quat="1.0 0.0 0.0 0.0">
                <inertial pos="0.000621 -0.000183 -0.078842" quat="1.0 0.0 0.0 0.0" mass="0.706556" diaginertia="0.0054 0.005499 0.00054" />
                <joint name="left_shoulder_roll_joint" axis="1 0 0" range="-0.061 2.993" />
                <geom class="visual" mesh="left_shoulder_roll_link"/>
                <body name="left_shoulder_yaw_link" pos="0.00122423638490546 0 -0.121194848262102" quat="0.9999955364438231 0.0 -0.002987824029380894 0.0">
                  <inertial pos="0.010005 0.000179 -0.069477" quat="1.0 0.0 0.0 0.0" mass="0.704662" diaginertia="0.004291 0.004367 0.000543" />
                  <joint name="left_shoulder_yaw_joint" axis="0 0 1" range="-2.556 2.556" />
                  <geom class="visual" mesh="left_shoulder_yaw_link"/>
                  <geom name="left_shoulder_yaw_collision" class="collision" size="0.035" fromto="0 0 -0.08 0 0 0.05"/>
                  <body name="left_elbow_link" pos="0.0140000000488655 0.000199986464082369 -0.0829500000002385" quat="0.9999955364438231 0.0 0.002987824029380894 0.0">
                    <inertial pos="-0.013174 0.003788 -0.080203" quat="1.0 0.0 0.0 0.0" mass="0.688008" diaginertia="0.00527 0.005332 0.000563" />
                    <joint name="left_elbow_joint" axis="0 1 0"  range="-2.3556 0" />
                    <geom class="visual" mesh="left_elbow_link"/>
                    <geom name="left_elbow_yaw_collision" class="collision" size="0.035" fromto="-0.01 0 -0.01 0.08 0 -0.01"/>
                    <body name="left_wrist_yaw_link" pos="-0.0132797235062217 -9.75487744990788E-05 -0.120575783591803" quat="1.0 0.0 0.0 0.0">
                      <inertial pos="7.6e-05 0.007263 -0.030679" quat="1.0 0.0 0.0 0.0" mass="0.360708" diaginertia="0.000612 0.000507 0.000208" />
                      <joint name="left_wrist_yaw_joint" axis="0 0 1"  range="-2.556 2.556" />
                      <geom class="visual" mesh="left_wrist_yaw_link"/>
                      <body name="left_wrist_pitch_link" pos="0.000490001227040848 0 -0.0819985359552045" quat="0.9999955364388414 0.0 -0.002987825696696517 0.0">
                        <joint name="left_wrist_pitch_joint" axis="0 1 0"  range="-0.558 0.558" />
                        <inertial pos="0.011479 0.002282 0.001703" quat="1.0 0.0 0.0 0.0" mass="0.292062" diaginertia="9.2e-05 0.000153 0.000163" />
                        <geom class="visual" mesh="left_wrist_pitch_link"/>
                        <geom name="left_wrist_collision" class="collision" size="0.035" fromto="-0.01 0 0 0.06 0 0"/>
                        <body name="left_wrist_roll_link" pos="0 0 0" quat="1.0 0.0 0.0 0.0">
                          <inertial pos="0.002935 -0.001499 -0.083026" quat="1.0 0.0 0.0 0.0" mass="0.30304" diaginertia="0.002667 0.002772 0.000211" />
                          <joint name="left_wrist_roll_joint" axis="1 0 0"  range="-1.571 0.724" />
                          <geom class="visual" mesh="left_wrist_roll_link"/>
                        </body>
                      </body>
                    </body>
                  </body>
                </body>
              </body>
            </body>
            <body name="right_shoulder_pitch_link" pos="0.00330093831251838 -0.143030971450747 0.241648201390685" quat="0.9945217227828823 -0.10453010529492318 0.0 0.0">
              <inertial pos="0.002721 -0.050304 3.4e-05" quat="1.0 0.0 0.0 0.0" mass="0.885544" diaginertia="0.003031 0.000681 0.002949" />
              <joint name="right_shoulder_pitch_joint" axis="0 1 0" range="-3.08 2.04" />
              <geom class="visual" mesh="right_shoulder_pitch_link"/>
              <body name="right_shoulder_roll_link" pos="-0.000499999994070091 -0.0495000000000002 0" quat="0.9999999970353809 0.0 7.700154638692909e-05 0.0">
                <joint name="right_shoulder_roll_joint" axis="1 0 0"  range="-2.993 0.061"/>
                <inertial pos="0.000598 0.000185 -0.079928" quat="1.0 0.0 0.0 0.0" mass="0.696963" diaginertia="0.0054 0.005489 0.00053" />
                <geom class="visual" mesh="right_shoulder_roll_link"/>
                <body name="right_shoulder_yaw_link" pos="0.000499999999999765 0 -0.121199999999934" quat="1.0 0.0 0.0 0.0">
                  <joint name="right_shoulder_yaw_joint" axis="0 0 1" range="-2.556 2.556" />
                  <inertial pos="0.010082 -0.000178 -0.069484" quat="1.0 0.0 0.0 0.0" mass="0.704661" diaginertia="0.004292 0.004366 0.000542" />
                  <geom class="visual" mesh="right_shoulder_yaw_link"/>
                  <geom name="right_shoulder_yaw_collision" class="collision" size="0.035" fromto="0 0 -0.08 0 0 0.05"/>

                  <body name="right_elbow_link" pos="0.0139999999999662 -0.0002000000000143 -0.0829500000000745" quat="1.0 0.0 0.0 0.0">
                    <joint name="right_elbow_joint" axis="0 1 0" range="-2.3556 0" />
                    <inertial pos="-0.013517 -0.003463 -0.080438" quat="1.0 0.0 0.0 0.0" mass="0.687932" diaginertia="0.005285 0.005356 0.000567" />
                    <geom class="visual" mesh="right_elbow_link"/>
                    <geom name="right_elbow_yaw_collision" class="collision" size="0.035" fromto="-0.01 0 -0.01 0.08 0 -0.01"/>

                    <body name="right_wrist_yaw_link" pos="-0.0140000017961392 9.7526096753231E-05 -0.120694276209686" quat="0.9999999998660591 0.0 0.0 1.6367095315399207e-05">
                      <joint name="right_wrist_yaw_joint" axis="0 0 1"  range="-2.556 2.556" />
                      <inertial pos="0.000153 -0.006979 -0.032069" quat="1.0 0.0 0.0 0.0" mass="0.372787" diaginertia="0.000696 0.000583 0.000218" />
                      <geom class="visual" mesh="right_wrist_yaw_link"/>
                      <body name="right_wrist_pitch_link" pos="0 0 -0.081799999999999" quat="0.999999999866059 0.0 0.0 -1.636709662658701e-05">
                        <joint name="right_wrist_pitch_joint" axis="0 1 0" range="-0.558 0.558"  />
                        <inertial pos="0.012092 -0.002544 0.001781" quat="1.0 0.0 0.0 0.0" mass="0.279175" diaginertia="8.3e-05 0.000151 0.000153" />
                        <geom name="right_wrist_collision" class="collision" size="0.035" fromto="-0.01 0 0 0.06 0 0"/>
                        <geom class="visual" mesh="right_wrist_pitch_link"/>
                        <body name="right_wrist_roll_link" pos="0 0 0" quat="1.0 0.0 0.0 0.0">
                          <joint name="right_wrist_roll_joint" axis="1 0 0" range="-0.724 1.571"  />
                          <inertial pos="0.003056 0.00138 -0.082799" quat="1.0 0.0 0.0 0.0" mass="0.303847" diaginertia="0.002666 0.002772 0.000212" />
                          <geom class="visual" mesh="right_wrist_roll_link"/>
                        </body>
                      </body>
                    </body>
                  </body>
                </body>
              </body>
            </body>
            <body name="head_yaw_link" pos="0.00834772789983268 0 0.309397077276121" quat="1.0 0.0 0.0 0.0">
              <joint name="head_yaw_joint" axis="0 0 1"  range="-0.366 0.366" />
              <inertial pos="-0.003139 0.001399 0.051838" quat="1.0 0.0 0.0 0.0" mass="0.720047" diaginertia="0.003861 0.003231 0.001103" />
              <geom class="visual"  mesh="head_yaw_link" />
              <body name="head_pitch_link" pos="0 0 0.0889" quat="1.0 0.0 0.0 0.0">
                <joint name="head_pitch_joint" axis="0 1 0"  range="-0.3838 0.3838" />
                <inertial pos="0.003033 -6e-05 0.004395" quat="1.0 0.0 0.0 0.0" mass="0.999287" diaginertia="0.002913 0.003598 0.002668" />
                <geom class="visual"  mesh="head_pitch_link" />
                <body name="imu_in_head_link" pos="0.0259998716312927 -8.2538922380776E-05 0.0175999960932565" quat="1.0 0.0 0.0 0.0">
                  <geom class="visual"  mesh="imu_in_head_link" />
                </body>
              </body>
            </body>
          </body>
        </body>
      </body>
    </body>
  </worldbody>

  <contact>
    <exclude body1="pelvis" body2="right_hip_roll_link"/>
    <exclude body1="pelvis" body2="left_hip_roll_link"/>
    <exclude body1="left_hip_roll_link" body2="left_hip_yaw_link" />
    <exclude body1="left_hip_yaw_link" body2="left_knee_link" />
    <exclude body1="right_hip_roll_link" body2="right_hip_yaw_link" />
    <exclude body1="right_hip_yaw_link" body2="right_knee_link" />
    <exclude body1="left_shoulder_roll_link" body2="left_shoulder_yaw_link" />
    <exclude body1="left_shoulder_yaw_link" body2="left_elbow_link" />
    <exclude body1="left_elbow_link" body2="left_wrist_yaw_link" />
    <exclude body1="right_shoulder_roll_link" body2="right_shoulder_yaw_link" />
    <exclude body1="right_shoulder_yaw_link" body2="right_elbow_link" />
    <exclude body1="right_elbow_link" body2="right_wrist_yaw_link" />
  </contact>

  <actuator>
    <position class="x2" kp="40.179" kv="2.558" forcerange="-88 88" name="left_hip_pitch_joint" joint="left_hip_pitch_joint"/>
    <position class="x2" kp="99.098" kv="6.309" forcerange="-139 139" name="left_hip_roll_joint" joint="left_hip_roll_joint"/>
    <position class="x2" kp="40.179" kv="2.558" forcerange="-88 88" name="left_hip_yaw_joint" joint="left_hip_yaw_joint"/>
    <position class="x2" kp="99.098" kv="6.309" forcerange="-139 139" name="left_knee_joint" joint="left_knee_joint"/>
    <position class="x2" kp="28.501" kv="1.814" forcerange="-50 50" name="left_ankle_pitch_joint" joint="left_ankle_pitch_joint"/>
    <position class="x2" kp="28.501" kv="1.814" forcerange="-50 50" name="left_ankle_roll_joint" joint="left_ankle_roll_joint"/>

    <position class="x2" kp="40.179" kv="2.558" forcerange="-88 88" name="right_hip_pitch_joint" joint="right_hip_pitch_joint"/>
    <position class="x2" kp="99.098" kv="6.309" forcerange="-139 139" name="right_hip_roll_joint" joint="right_hip_roll_joint"/>
    <position class="x2" kp="40.179" kv="2.558" forcerange="-88 88" name="right_hip_yaw_joint" joint="right_hip_yaw_joint"/>
    <position class="x2" kp="99.098" kv="6.309" forcerange="-139 139" name="right_knee_joint" joint="right_knee_joint"/>
    <position class="x2" kp="28.501" kv="1.814" forcerange="-50 50" name="right_ankle_pitch_joint" joint="right_ankle_pitch_joint"/>
    <position class="x2" kp="28.501" kv="1.814" forcerange="-50 50" name="right_ankle_roll_joint" joint="right_ankle_roll_joint"/>

    <position class="x2" kp="40.179" kv="2.558" forcerange="-88 88" name="waist_yaw_joint" joint="waist_yaw_joint"/>
    <position class="x2" kp="28.501" kv="1.814" forcerange="-50 50" name="waist_roll_joint" joint="waist_roll_joint"/>
    <position class="x2" kp="28.501" kv="1.814" forcerange="-50 50" name="waist_pitch_joint" joint="waist_pitch_joint"/>

    <position class="x2" kp="14.251" kv="0.907" forcerange="-25 25" name="left_shoulder_pitch_joint" joint="left_shoulder_pitch_joint"/>
    <position class="x2" kp="14.251" kv="0.907" forcerange="-25 25" name="left_shoulder_roll_joint" joint="left_shoulder_roll_joint"/>
    <position class="x2" kp="14.251" kv="0.907" forcerange="-25 25" name="left_shoulder_yaw_joint" joint="left_shoulder_yaw_joint"/>
    <position class="x2" kp="14.251" kv="0.907" forcerange="-25 25" name="left_elbow_joint" joint="left_elbow_joint"/>
    <position class="x2" kp="14.251" kv="0.907" forcerange="-25 25" name="left_wrist_roll_joint" joint="left_wrist_roll_joint"/>
    <position class="x2" kp="16.778" kv="1.068" forcerange="-5 5" name="left_wrist_pitch_joint" joint="left_wrist_pitch_joint"/>
    <position class="x2" kp="16.778" kv="1.068" forcerange="-5 5" name="left_wrist_yaw_joint" joint="left_wrist_yaw_joint"/>

    <position class="x2" kp="14.251" kv="0.907" forcerange="-25 25" name="right_shoulder_pitch_joint" joint="right_shoulder_pitch_joint"/>
    <position class="x2" kp="14.251" kv="0.907" forcerange="-25 25" name="right_shoulder_roll_joint" joint="right_shoulder_roll_joint"/>
    <position class="x2" kp="14.251" kv="0.907" forcerange="-25 25" name="right_shoulder_yaw_joint" joint="right_shoulder_yaw_joint"/>
    <position class="x2" kp="14.251" kv="0.907" forcerange="-25 25" name="right_elbow_joint" joint="right_elbow_joint"/>
    <position class="x2" kp="14.251" kv="0.907" forcerange="-25 25" name="right_wrist_roll_joint" joint="right_wrist_roll_joint"/>
    <position class="x2" kp="16.778" kv="1.068" forcerange="-5 5" name="right_wrist_pitch_joint" joint="right_wrist_pitch_joint"/>
    <position class="x2" kp="16.778" kv="1.068" forcerange="-5 5" name="right_wrist_yaw_joint" joint="right_wrist_yaw_joint"/>

    <position class="x2" kp="16.778" kv="1.068" forcerange="-5 5" name="head_yaw_joint" joint="head_yaw_joint"/>
    <position class="x2" kp="16.778" kv="1.068" forcerange="-5 5" name="head_pitch_joint" joint="head_pitch_joint"/>
  </actuator>

  <sensor>
    <velocimeter site="imu_in_pelvis" name="pelvis_local_linvel"/>
    <gyro site="imu_in_pelvis" name="pelvis_gyro" cutoff="34.9" noise="0.0005"/>
    <accelerometer site="imu_in_pelvis" name="pelvis_acceleration" cutoff="157" noise="0.01"/>
    <framezaxis objtype="site" objname="imu_in_pelvis" name="pelvis_upvector"/>

    <gyro site="imu_in_torso" name="torso_gyro" cutoff="34.9" noise="0.0005"/>
    <accelerometer site="imu_in_torso" name="torso_acceleration" cutoff="157" noise="0.01"/>
    <framezaxis objtype="site" objname="imu_in_torso"  name="torso_upvector"/>

    <framepos objtype="site" objname="left_foot" name="left_foot_pos"/>
    <framequat objtype="site" objname="left_foot" name="left_foot_quat"/>
    <framezaxis objtype="site" objname="left_foot" name="left_foot_upvector"/>

    <framepos objtype="site" objname="right_foot" name="right_foot_pos"/>
    <framequat objtype="site" objname="right_foot" name="right_foot_quat"/>
    <framezaxis objtype="site" objname="right_foot" name="right_foot_upvector"/>
  </sensor>

</mujoco>

